Workbook

Sheet Overview
A1: APEX — Talent, Alumni & Network
A2: Yearly plan · September 2026 – August 2027
A3: Owner: Nadav Delgo · Reviewed weekly with Avishag · Built from the role definition (§ references point at it)
A5: אתה ה־Human Node של APEX. וככל שאתה מצליח יותר בתפקיד, אני צריכה להיות פחות באמצע.
A6: — the role definition, §25
A8: Where things stand
A9: =COUNTA(Roster!$B$2:$B$98) | C9: =COUNTA('Call Schedule'!$E$2:$E$190) | E9: =COUNTIF('Call Schedule'!$L$2:$L$190,"done") | G9: =COUNTA(Roster!$R$2:$R$98)
A10: Alumni | C10: Conversations planned | E10: Done so far | G10: Roster rows with a next action
A13: Who the alumni are
A14: Tier sets call frequency and nothing else. It is not a ranking, and the matching engine ignores it — a tier-C engineer at Wiz is still a first-class referral path into Wiz.
A16: Tier | B16: Who | C16: Calls/yr | D16: People | E16: Calls/yr total | F16: Done | G16: % done
A17: A | B17: Founders, stealth builders, people at a transition point (§5) | C17: 3 | D17: =COUNTIF(Roster!$K$2:$K$98,$A17) | E17: =COUNTIF('Call Schedule'!$G$2:$G$190,$A17) | F17: =COUNTIFS('Call Schedule'!$G$2:$G$190,$A17,'Call Schedule'!$L$2:$L$190,"done") | G17: =IF($E17=0,0,$F17/$E17)
A18: B | B18: Seniority or research standing — office hours, referrals, intros | C18: 2 | D18: =COUNTIF(Roster!$K$2:$K$98,$A18) | E18: =COUNTIF('Call Schedule'!$G$2:$G$190,$A18) | F18: =COUNTIFS('Call Schedule'!$G$2:$G$190,$A18,'Call Schedule'!$L$2:$L$190,"done") | G18: =IF($E18=0,0,$F18/$E18)
A19: C | B19: No verified role (the roll-up backlog) + slower-moving ICs | C19: 1 | D19: =COUNTIF(Roster!$K$2:$K$98,$A19) | E19: =COUNTIF('Call Schedule'!$G$2:$G$190,$A19) | F19: =COUNTIFS('Call Schedule'!$G$2:$G$190,$A19,'Call Schedule'!$L$2:$L$190,"done") | G19: =IF($E19=0,0,$F19/$E19)
A20: Total | D20: =SUM($D$17:$D$19) | E20: =SUM($E$17:$E$19) | F20: =SUM($F$17:$F$19) | G20: =IF($E20=0,0,$F20/$E20)
A22: Rotation: 3–4 conversations a week, Sunday to Wednesday, across 50 working weeks. Thursday stays clear for the weekly report. חגים are excluded — no call is scheduled on one.
A25: The year in four movements
A26: Quarter | B26: Theme | C26: The test it has to pass | D26: Calls | E26: Done | F26: % done
A27: Q1 · Sep–Nov 2026 | B27: Know them | C27: The 90-day test (§24) — every question answerable without asking anyone | D27: =COUNTIF('Call Schedule'!$D$2:$D$190,"Q1") | E27: =COUNTIFS('Call Schedule'!$D$2:$D$190,"Q1",'Call Schedule'!$L$2:$L$190,"done") | F27: =IF($D27=0,0,$E27/$D27)
A28: Q2 · Dec–Feb | B28: Harness them | C28: Alumni move from receiving value to giving it (§4) | D28: =COUNTIF('Call Schedule'!$D$2:$D$190,"Q2") | E28: =COUNTIFS('Call Schedule'!$D$2:$D$190,"Q2",'Call Schedule'!$L$2:$L$190,"done") | F28: =IF($D28=0,0,$E28/$D28)
A29: Q3 · Mar–May 2027 | B29: Compound | C29: Alumni-to-alumni introductions outnumber the ones Nadav brokers | D29: =COUNTIF('Call Schedule'!$D$2:$D$190,"Q3") | E29: =COUNTIFS('Call Schedule'!$D$2:$D$190,"Q3",'Call Schedule'!$L$2:$L$190,"done") | F29: =IF($D29=0,0,$E29/$D29)
A30: Q4 · Jun–Aug 2027 | B30: Institutionalise | C30: A month without Avishag, run for real — does the network still strengthen? | D30: =COUNTIF('Call Schedule'!$D$2:$D$190,"Q4") | E30: =COUNTIFS('Call Schedule'!$D$2:$D$190,"Q4",'Call Schedule'!$L$2:$L$190,"done") | F30: =IF($D30=0,0,$E30/$D30)
A33: How to use this workbook
A34: Yellow cells are yours to fill in. | B34: Everything else is generated from config/network/roster.csv and the call rotation, and is overwritten when the workbook is rebuilt.
A35: Call Schedule | B35: One row per planned conversation. Set Status to 'done' — the row turns green and every count above moves.
A36: Roster | B36: The source of truth for people. After each call fill Now, Needs, Can help, Last contact and above all NEXT ACTION.
A37: KPI Tracker | B37: Weekly numbers. The call counts and the funnel compute themselves; the rest you type.
A38: Q1 90-Day Test | B38: The eight questions §24 says must be answerable in ninety days.
A39: Projects | B39: Coffee Club, SF, Office Hours, Alumni Roll-Up — with dates.
A41: Example of a filled roster row
A42: Now / current goal | B42: Leaving Meta in November, starting a company
A43: Needs | B43: Technical co-founder; two intros in AI infra
A44: Can help with | B44: ML pipelines; interviewing; referrals into Meta
A45: Tie strength | B45: Engaged
A46: Last contact | B46: 14/09/2026
A47: Source | B47: call 14/09
A48: NEXT ACTION | B48: Intro to Guy Goldenberg (Wiz) on the ML infra opening
A49: Due | B49: 21/09/2026
A50: Illustration only — this is not a real alum, and no row like it exists in the Roster sheet.
A53: Where the data came from
...

Sheet Call Schedule
A1: Date | B1: Day | C1: Wk | D1: Qtr | E1: Who | F1: Cohort | G1: Tier | H1: Channel | I1: What the call is for | J1: Phone | K1: Email | L1: Status | M1: Notes from the call
A2: 46271 | B2: Sun | C2: 1 | D2: Q1 | E2: Assaf Monsa | F2: #1 | G2: A | H2: phone | I2: Node candidate. What can they open for our alumni, and would they give office hours? | J2: +972544319991 | K2: assafmonsa@gmail.com
A3: 46272 | B3: Mon | C3: 1 | D3: Q1 | E3: Danny Grander | F3: #1 | G3: A | H3: phone | I3: Node candidate — founded Snyk. What can they open for our alumni, and would they give office hours? | J3: +972507616594 | K3: danny.grander@gmail.com
A4: 46273 | B4: Tue | C4: 1 | D4: Q1 | E4: Eldad Kepten | F4: #1 | G4: B | H4: linkedin | I4: What can they give — office hours, referrals, mentoring? And what do they need from us right now?
A5: 46274 | B5: Wed | C5: 1 | D5: Q1 | E5: Aviel Adler | F5: #1 | G5: C | H5: phone | I5: Stay current — what are they working on now, and what would help? | J5: +972549954666 | K5: avieladler@gmail.com
A6: 46279 | B6: Mon | C6: 2 | D6: Q1 | E6: Eyal Kraft | F6: #1 | G6: A | H6: linkedin | I6: Founding track — building this year? What is the blocker, is co-founder the gap, and who should they meet?
A7: 46280 | B7: Tue | C7: 2 | D7: Q1 | E7: Eran Hertzmann | F7: #1 | G7: B | H7: phone | I7: What can they give — office hours, referrals, mentoring? And what do they need from us right now? | J7: +972545424895 | K7: eran.hertzmann@gmail.com
A8: 46281 | B8: Wed | C8: 2 | D8: Q1 | E8: Gai Gutherz | F8: #1 | G8: B | H8: linkedin | I8: What can they give — office hours, referrals into Miggo, mentoring? And what do they need from us right now?
A9: 46282 | B9: Thu | C9: 2 | D9: Q1 | E9: Daniel Ohayon | F9: #1 | G9: C | H9: phone | I9: Stay current — what are they working on in research now, and what would help? | J9: +972524056440
A10: 46287 | B10: Tue | C10: 3 | D10: Q1 | E10: Inbal Beracha | F10: #1 | G10: A | H10: linkedin | I10: Founding track — building this year? What is the blocker, is co-founder the gap, and who should they meet?
A11: 46288 | B11: Wed | C11: 3 | D11: Q1 | E11: Meir Adest | F11: #1 | G11: A | H11: linkedin | I11: Node candidate. What can they open for our alumni, and would they give office hours?
A12: 46289 | B12: Thu | C12: 3 | D12: Q1 | E12: Michal Shilo | F12: #1 | G12: B | H12: phone | I12: What can they give — office hours, referrals, mentoring? And what do they need from us right now? | J12: +972524598022 | K12: michalshilo6@gmail.com
A13: 46299 | B13: Sun | C13: 4 | D13: Q1 | E13: Michael Kellner | F13: #1 | G13: A | H13: phone | I13: Node candidate — founded SendBlocks. What can they open for our alumni, and would they give office hours? | J13: +972545311213 | K13: mike53il@gmail.com
A14: 46300 | B14: Mon | C14: 4 | D14: Q1 | E14: Nadav Zemach | F14: #1 | G14: B | H14: linkedin | I14: What can they give — office hours, referrals, mentoring? And what do they need from us right now?
A15: 46301 | B15: Tue | C15: 4 | D15: Q1 | E15: Noy Duany | F15: #1 | G15: B | H15: linkedin | I15: What can they give — office hours, referrals into Hopper Security, mentoring? And what do they need from us right now?
A16: 46302 | B16: Wed | C16: 4 | D16: Q1 | E16: Dror Ben Eliezer | F16: #1 | G16: C | H16: linkedin | I16: Stay current — what are they working on in product-gtm now, and what would help?
A17: 46306 | B17: Sun | C17: 5 | D17: Q1 | E17: Uri Shaked | F17: #1 | G17: A | H17: linkedin | I17: Node candidate. What can they open for our alumni, and would they give office hours?
A18: 46307 | B18: Mon | C18: 5 | D18: Q1 | E18: Zvi Wexlstein | F18: #1 | G18: A | H18: email | I18: Transition point — what are they building or moving toward, what is the blocker, and who should they meet? | K18: zviwex@gmail.com
A19: 46308 | B19: Tue | C19: 5 | D19: Q1 | E19: Ohad Amosy | F19: #1 | G19: B | H19: linkedin | I19: What can they give — office hours, referrals, mentoring? And what do they need from us right now?
A20: 46309 | B20: Wed | C20: 5 | D20: Q1 | E20: Omer Hay | F20: #1 | G20: B | H20: linkedin | I20: What can they give — office hours, referrals, mentoring? And what do they need from us right now?
A21: 46313 | B21: Sun | C21: 6 | D21: Q1 | E21: Rami Anati | F21: #1 | G21: B | H21: linkedin | I21: What can they give — office hours, referrals, mentoring? And what do they need from us right now?
A22: 46314 | B22: Mon | C22: 6 | D22: Q1 | E22: Eran Hirsch | F22: #1 | G22: C | H22: phone | I22: Stay current — what are they working on in infra-systems now, and what would help? | J22: +972548303525 | K22: eranhirsch@gmail.com
A23: 46315 | B23: Tue | C23: 6 | D23: Q1 | E23: Almog Zer | F23: #2 | G23: A | H23: phone | I23: Founding track — building this year? What is the blocker, is co-founder the gap, and who should they meet? | J23: +972507363131 | K23: almogx3@gmail.com
A24: 46320 | B24: Sun | C24: 7 | D24: Q1 | E24: Roee Yaron | F24: #1 | G24: B | H24: linkedin | I24: What can they give — office hours, referrals into Ministry of Defense, mentoring? And what do they need from us right now?
A25: 46321 | B25: Mon | C25: 7 | D25: Q1 | E25: Nir Yaron | F25: #1 | G25: C | H25: linkedin | I25: Roll-up — no verified role on file. What are they doing now, where are they heading, and what do they need?
A26: 46323 | B26: Wed | C26: 7 | D26: Q1 | E26: Bar Matityahu | F26: #2 | G26: A | H26: phone | I26: Founding track — building this year? What is the blocker, is co-founder the gap, and who should they meet? | J26: +972525892000 | K26: barmatit@gmail.com
A27: 46324 | B27: Thu | C27: 7 | D27: Q1 | E27: Benny Rousso | F27: #2 | G27: A | H27: phone | I27: Node candidate — founded Xcardia. What can they open for our alumni, and would they give office hours? | J27: +972544345653 | K27: rousso.benny@gmail.com
A28: 46327 | B28: Sun | C28: 8 | D28: Q1 | E28: Ronen Tur | F28: #1 | G28: B | H28: linkedin | I28: What can they give — office hours, referrals, mentoring? And what do they need from us right now?
A29: 46328 | B29: Mon | C29: 8 | D29: Q1 | E29: Shachar Cohen | F29: #1 | G29: B | H29: linkedin | I29: What can they give — office hours, referrals, mentoring? And what do they need from us right now?
A30: 46329 | B30: Tue | C30: 8 | D30: Q1 | E30: Gal Wiernik | F30: #2 | G30: A | H30: phone | I30: Node candidate — founded Edwin. What can they open for our alumni, and would they give office hours? | J30: +972502338655 | K30: galwiernik@gmail.com
A31: 46330 | B31: Wed | C31: 8 | D31: Q1 | E31: Guy Yoshpe | F31: #2 | G31: A | H31: phone | I31: Founding track — building this year? What is the blocker, is co-founder the gap, and who should they meet? | J31: +972508717313 | K31: yoshpe@gmail.com
A32: 46334 | B32: Sun | C32: 9 | D32: Q1 | E32: Shai Elroy | F32: #1 | G32: B | H32: linkedin | I32: What can they give — office hours, referrals, mentoring? And what do they need from us right now?
A33: 46335 | B33: Mon | C33: 9 | D33: Q1 | E33: Hila Shmuel | F33: #2 | G33: A | H33: phone | I33: Node candidate — founded Cabinet (AI workspace). What can they open for our alumni, and would they give office hours? | J33: +972508871171 | K33: hila4321@gmail.com
A34: 46336 | B34: Tue | C34: 9 | D34: Q1 | E34: Aviel Zecharia | F34: #2 | G34: B | H34: phone | I34: What can they give — office hours, referrals into Palo Alto Networks, mentoring? And what do they need from us right now? | J34: +972547260058 | K34: avielz1199@gmail.com
A35: 46337 | B35: Wed | C35: 9 | D35: Q1 | E35: Benzion Kossowsky | F35: #2 | G35: C | H35: phone | I35: Stay current — what are they working on now, and what would help? | J35: +972543315821 | K35: benzionkossowsky@gmail.com
A36: 46341 | B36: Sun | C36: 10 | D36: Q1 | E36: Iddan Golomb | F36: #2 | G36: A | H36: phone | I36: Node candidate — founded Sayata. What can they open for our alumni, and would they give office hours? | J36: +972542421974 | K36: igolomb@gmail.com
A37: 46342 | B37: Mon | C37: 10 | D37: Q1 | E37: Jonathan Gilat | F37: #2 | G37: A | H37: phone | I37: Node candidate — founded Medida AI. What can they open for our alumni, and would they give office hours? | J37: +972528198278 | K37: jonathan@medida.ai
A38: 46343 | B38: Tue | C38: 10 | D38: Q1 | E38: Eyal Horowicz | F38: #2 | G38: B | H38: phone | I38: What can they give — office hours, referrals into Claroty (DS Team Leader per roster), mentoring? And what do they need from us right now? | J38: +972506228892 | K38: eyalhoro6@gmail.com
A39: 46344 | B39: Wed | C39: 10 | D39: Q1 | E39: Kfir Shoar | F39: #2 | G39: C | H39: linkedin | I39: Stay current — still at Cyera? What are they working on in security, and what would help?
A40: 46348 | B40: Sun | C40: 11 | D40: Q1 | E40: Liran Markin | F40: #2 | G40: A | H40: phone | I40: Node candidate — founded Edwin. What can they open for our alumni, and would they give office hours? | J40: +972544911254 | K40: liran.markin@gmail.com
...

Sheet Roster
A1: ID | B1: Name | C1: שם בעברית | D1: Cohort | E1: Founder track | F1: Unit | G1: Company | H1: Role | I1: Location | J1: Domain | K1: Tier | L1: Tie strength | M1: Now / current goal | N1: Needs | O1: Can help with | P1: Last contact | Q1: Source | R1: NEXT ACTION | S1: Due | T1: LinkedIn | U1: Email | V1: Phone | W1: Source note (GPU screen, 15/07) | X1: Notes
A2: 6 | B2: Assaf Monsa | D2: #1 | F2: Talpiot | H2: Co-Founder, CTO & VP R&D, D-Fend Solutions | I2: Netanya, Israel | J2: security | K2: A | T2: https://www.linkedin.com/in/assaf-monsa-72a84/ | U2: assafmonsa@gmail.com | V2: +972544319991 | W2: Founded and scaled a real-time RF/hardware company (counter-drone) as CTO/VP R&D - proven physical-systems founder. Domain gap (RF, not GPU/power) and committed to D-Fend. | X2: [dex import] education: תלפיות · tags: Apex Newsletter,Signed To Apex,Fireside Chat,19/10/25 Closing Event,Apex Grad
A3: 1 | B3: Aviel Adler | D3: #1 | H3: R&D | I3: Israel | K3: C | T3: https://www.linkedin.com/in/aviel-a-a87b2612/ | U3: avieladler@gmail.com | V3: +972549954666 | W3: No company/role data in roster and no reliable public technical record found against the criteria (GPU systems, power, real-time control). | X3: [dex import] education: תלפיות · tags: Apex Newsletter,Signed To Apex,Fireside Chat,Apex Grad
A4: 9 | B4: Daniel Ohayon | D4: #1 | F4: Psagot | H4: MSc student, Technion | I4: Jerusalem District, Israel | J4: research | K4: C | T4: https://www.linkedin.com/in/daniel-ohayon-45b68513a | V4: +972524056440 | W4: Graduate student, Psagot. Insufficient production record to score above the average band.
A5: 8 | B5: Danny Grander | D5: #1 | F5: ARAM | G5: Snyk | H5: Co-Founder | I5: Israel | J5: security | K5: A | T5: https://www.linkedin.com/in/grander | U5: danny.grander@gmail.com | V5: +972507616594 | W5: World-class 0-to-1 founder signal (Snyk) and now angel - but zero domain overlap with GPU/power. Not an operator fit; top-tier angel/advisor target for Joulix's next round. | X5: [dex import] met with: Can help Apex · education: ארם · tags: Apex Donor,PEF,Apex Newsletter,Mega Connector,Signed To Apex,Fireside Chat,Coffee Avishag,19/10/25 Closing Event,25/2/2026 - Closing Event,Apex Grad
A6: 10 | B6: Dror Ben Eliezer | D6: #1 | F6: Talpiot | H6: Independent Consultant, ex-Nike | J6: product-gtm | K6: C | T6: https://www.linkedin.com/in/dror-ben-eliezer-b084406/ | W6: Consulting profile, no evidence of hands-on systems/infra work relevant to the criteria.
A7: 5 | B7: Eldad Kepten | D7: #1 | F7: Talpiot | H7: Leading Data Scientist (research-to-product) | J7: ai-ml | K7: B | T7: https://www.linkedin.com/in/eldad-kepten-441ba124/ | W7: Senior data scientist bridging research to product. Relevant analytical horsepower, no systems/power/GPU evidence.
A8: 20 | B8: Eran Hertzmann | D8: #1 | F8: Talpiot | H8: Product Executive, AI digital health | I8: Tel-Aviv District, Israel | J8: ai-ml | K8: B | T8: https://www.linkedin.com/in/eran-hertzmann-24a400 | U8: eran.hertzmann@gmail.com | V8: +972545424895 | W8: Product executive, health tech. Not a technical founding fit for this domain. | X8: [dex import] education: תלפיות · tags: Apex Newsletter,Signed To Apex,Fireside Chat,Apex Grad
A9: 19 | B9: Eran Hirsch | D9: #1 | F9: ARAM | H9: Freelance Full-Stack, ex-Meta | I9: Givatayim, Tel-Aviv District, Israel | J9: infra-systems | K9: C | T9: https://www.linkedin.com/in/eranhirsch | U9: eranhirsch@gmail.com | V9: +972548303525 | W9: Ex-Meta full-stack freelancer. Application layer; no systems/power depth in public record. | X9: [dex import] education: אר"ם · tags: Apex Newsletter,Signed To Apex,Fireside Chat,19/10/25 Closing Event,Apex Grad
A10: 4 | B10: Eyal Kraft | D10: #1 | F10: ARAM | G10: Stealth | H10: CTO | K10: A | T10: https://www.linkedin.com/in/eyalkraft | W10: CTO of a stealth company - cannot assess technical fit without knowing the domain, and availability is presumptively zero. Track, don't pitch.
A11: 7 | B11: Gai Gutherz | D11: #1 | F11: Talpiot | G11: Miggo | H11: Head of Technical Product | J11: security | K11: B | T11: https://www.linkedin.com/in/gai-gutherz | W11: Technical product leadership in appsec. No systems/power/GPU record.
A12: 18 | B12: Inbal Beracha | D12: #1 | F12: Talpiot | G12: Stealth | H12: Founding Engineer | K12: A | T12: https://www.linkedin.com/in/inbal-beracha-a668ab182/ | W12: Founding engineer at stealth - domain unknown, availability presumptively zero.
A13: 11 | B13: Meir Adest | D13: #1 | F13: Talpiot | H13: Co-Founder, SolarEdge Technologies | J13: hardware-embedded | K13: A | T13: https://www.linkedin.com/in/meiradest/ | W13: Co-founded SolarEdge - the defining company in power-optimization electronics (per-panel DC optimization, i.e. 'maximize output per installed watt'), scaled to a global public company. Exact business logic of Joulix in a different asset class. Won't join as operator; exceptional as founding chairman / technical advisor / seed investor.
A14: 12 | B14: Michael Kellner | D14: #1 | F14: Talpiot | G14: SendBlocks | H14: Co-Founder & CTO | K14: A | T14: https://www.linkedin.com/in/michael-kellner-689258206 | U14: mike53il@gmail.com | V14: +972545311213 | W14: Infra founder-CTO (blockchain data infrastructure). Real infra chops, committed elsewhere, no power/GPU record. | X14: [dex import] education: תלפיות · tags: Apex Newsletter,Signed To Apex,Fireside Chat,25/2/2026 - Closing Event,Apex Grad
A15: 13 | B15: Michal Shilo | D15: #1 | F15: Talpiot | H15: Data Scientist | I15: Tel Aviv-Yafo, Tel Aviv District, Israel | J15: ai-ml | K15: B | T15: https://www.linkedin.com/in/michal-shilo-ba3002190/ | U15: michalshilo6@gmail.com | V15: +972524598022 | W15: Data scientist, Talpiot. No systems/power/GPU evidence. | X15: [dex import] education: תלפיות · tags: Apex Newsletter,Signed To Apex,Fireside Chat,Apex Grad
A16: 14 | B16: Nadav Zemach | D16: #1 | F16: Talpiot | H16: Director Advisor, Ministry of Finance | J16: product-gtm | K16: B | T16: https://www.linkedin.com/in/nadav-zemach-477a42365/ | W16: Government finance advisor - not a technical fit for a founding team. Separately valuable for sovereign-AI / regulatory / grant angles.
A17: 16 | B17: Nir Yaron | D17: #1 | F17: Talpiot | H17: Unknown | K17: C | T17: https://www.linkedin.com/in/nir-yaron-886051241 | W17: No role data in roster/alumni page and no reliable public technical record found.
A18: 15 | B18: Noy Duany | D18: #1 | F18: ARAM | G18: Hopper Security | H18: R&D Team Lead | J18: security | K18: B | T18: https://www.linkedin.com/in/noyduany/ | W18: Cyber R&D team lead. Solid engineer-leader, wrong domain.
A19: 2 | B19: Ohad Amosy | D19: #1 | F19: Talpiot | H19: AI-COE / ML researcher (Bar-Ilan, Chechik lab) | J19: research | K19: B | T19: https://il.linkedin.com/in/ohad-amosy | W19: Published ML researcher (WACV, EMNLP; federated learning, hypernetworks) incl. a neural-network-driven QAOA optimization paper and co-authorship with NVIDIA Research-affiliated lab. Strong optimization/ML brain for the control-policy side; no GPU systems or power production record.
A20: 17 | B20: Omer Hay | D20: #1 | F20: Psagot | H20: Software Engineer / R&D Team Lead | I20: Israel | J20: infra-systems | K20: B | T20: https://www.linkedin.com/in/hay-omer | W20: Generalist SWE/team lead. No domain evidence.
A21: 24 | B21: Rami Anati | D21: #1 | F21: Talpiot | H21: Team Lead / Back-End Project Manager | J21: infra-systems | K21: B | T21: https://www.linkedin.com/in/ramianati | W21: Backend team lead/PM. No domain evidence.
A22: 23 | B22: Roee Yaron | D22: #1 | F22: Talpiot | G22: Ministry of Defense | H22: Physicist | J22: quantum-physics | K22: B | W22: Defense physicist, Talpiot. Hard-science depth, no software-infrastructure record.
A23: 22 | B23: Ronen Tur | D23: #1 | F23: Talpiot | H23: Director of Algorithms & Deep Learning | J23: ai-ml | K23: B | T23: https://www.linkedin.com/in/ronen-tur-641a0a18/ | W23: Senior algorithms/DL leadership - relevant to the optimization brain of a power-control loop, but no public GPU/power specifics.
A24: 25 | B24: Shachar Cohen | D24: #1 | F24: Talpiot | H24: Software R&D Engineer & Manager | J24: product-gtm | K24: B | T24: https://www.linkedin.com/in/shachar-cohen-480b86205 | W24: SW R&D engineer/manager, Talpiot. No domain evidence.
A25: 26 | B25: Shai Elroy | D25: #1 | F25: Psagot | H25: R&D Team Lead, Cyber | J25: security | K25: B | T25: https://www.linkedin.com/in/shai-elroy | W25: Cyber R&D team lead. Wrong domain.
A26: 3 | B26: Uri Shaked | D26: #1 | F26: ARAM / Founder | H26: Founder, Wokwi + TinyTapeout | J26: hardware-embedded | K26: A | T26: https://www.linkedin.com/in/urishaked/ | W26: Built Wokwi (embedded/silicon simulation) and active in open silicon (TinyTapeout) - rare HW/SW boundary depth, exactly the instinct a firmware-adjacent power layer needs. No GPU DVFS/data-center record; committed to his own products. Best used as technical advisor.
A27: 21 | B27: Zvi Wexlstein | D27: #1 | E27: yes | F27: ARAM | H27: Software Architect, Polar (IBM) | J27: infra-systems | K27: A | T27: https://www.linkedin.com/in/zvi-wexlstein | U27: zviwex@gmail.com | W27: Software architect at Polar/IBM; Founder Track signal. Solid architect, no power/GPU record. | X27: [dex import] tags: Fireside Chat
A28: 30 | B28: Almog Zer | D28: #2 | F28: Psagot | G28: Stealth | H28: R&D Group Lead | I28: Israel | K28: A | T28: https://www.linkedin.com/in/almog-zer-865897118 | U28: almogx3@gmail.com | V28: +972507363131 | W28: Group lead at stealth - domain unknown, availability low. | X28: [dex import] military course: טו · met with: Can help Apex · warm intro via: Lutati · education: פסגות · tags: Fireside Chat,Signed To Apex,Apex Newsletter,Watchlist,25/2/2026 - Closing Event,Apex Grad
A29: 27 | B29: Aviel Zecharia | D29: #2 | F29: ARAM | G29: Palo Alto Networks | H29: Architect | I29: Rishon LeZion, Israel | J29: security | K29: B | T29: https://www.linkedin.com/in/aviel-zecharia-832a66131/ | U29: avielz1199@gmail.com | V29: +972547260058 | W29: Security architect at PAN. Strong engineer, security domain. | X29: [dex import] military course: 20 · education: אר"ם · tags: 25/2/2026 - Closing Event,Fireside Chat,Apex Newsletter,Signed To Apex,Architect Cohort #2,Apex Grad
A30: 33 | B30: Bar Matityahu | D30: #2 | F30: Psagot | G30: Stealth | H30: Founder | I30: Tel-Aviv District, Israel | K30: A | T30: https://www.linkedin.com/in/bar-matityahu | U30: barmatit@gmail.com | V30: +972525892000 | W30: Stealth founder - unknowable and unavailable. | X30: [dex import] military course: מחזור י - חשמל פיזיקה טכניון · education: פסגות · tags: 25/2/2026 - Closing Event,Fireside Chat,Apex Newsletter,Signed To Apex,Architect Cohort #2,Apex Grad
A31: 32 | B31: Benny Rousso | D31: #2 | F31: Talpiot | G31: Xcardia | H31: CEO & Founder | I31: Tel Aviv, Tel-Aviv District, Israel | J31: health-bio | K31: A | T31: http://linkedin.com/in/benny-rousso-27832b32b | U31: rousso.benny@gmail.com | V31: +972544345653 | W31: Founder-CEO in medical imaging. Founder DNA, wrong domain, committed. | X31: [dex import] military course: 9 · education: תלפיות · tags: 25/2/2026 - Closing Event,Fireside Chat,Apex Newsletter,Signed To Apex,Architect Cohort #2,Apex Grad
A32: 31 | B32: Benzion Kossowsky | D32: #2 | F32: ARAM | H32: OneStep | I32: West Jerusalem, Jerusalem District, Israel | K32: C | T32: https://www.linkedin.com/in/benzionkossowsky | U32: benzionkossowsky@gmail.com | V32: +972543315821 | W32: At OneStep (digital health/motion analysis). No domain evidence. | X32: [dex import] military course: 22 · education: אר״מ · tags: Fireside Chat,Apex Newsletter,Signed To Apex,25/2/2026 - Closing Event,Architect Cohort #2,Apex Grad
A33: 28 | B33: Eyal Horowicz | D33: #2 | F33: Talpiot | G33: Claroty (DS Team Leader per roster) | H33: Senior SWE | I33: Tel-Aviv District, Israel | J33: security | K33: B | T33: https://www.linkedin.com/in/eyal-horowicz | U33: eyalhoro6@gmail.com | V33: +972506228892 | W33: Senior engineer at Claroty (OT/ICS security) - adjacent to industrial control environments, but security-side, not performance/power. | X33: [dex import] military course: 36 · education: תלפיות · tags: Fireside Chat,Apex Newsletter,Signed To Apex,25/2/2026 - Closing Event,Architect Cohort #2,Apex Grad
A34: 36 | B34: Gal Wiernik | D34: #2 | F34: Arazim | G34: Edwin | H34: CTO | I34: Tel Aviv, Tel-Aviv District, Israel | J34: ai-ml | K34: A | T34: https://www.linkedin.com/in/galwiernik | U34: galwiernik@gmail.com | V34: +972502338655 | W34: Genuine HPC pedigree: co-author of an IPDPS 2024 paper on fast, stable matrix multiplication - performance engineering of the exact kernels GPUs burn watts on - plus AI-infra experience and TAU research excellence awards. Now CTO at Edwin, so likely unavailable; skills-wise the top available-market operator in the roster. | X34: [dex import] military course: ארזים ט׳ · met with: NA · education: ארזים · tags: Apex Newsletter,Signed To Apex,25/2/2026 - Closing Event,Architect Cohort #2,Fireside Chat,Apex Grad
A35: 35 | B35: Gil Raytan | D35: #2 | F35: Psagot | G35: Remitly (AI/ML) | H35: Director of Engineering | I35: Israel | J35: ai-ml | K35: B | T35: https://www.linkedin.com/in/gil-raytan/ | U35: gil.raytan@gmail.com | V35: +972544322242 | W35: Eng leadership over AI/ML at fintech scale. VP-Eng-later-stage profile, not founding GPU-systems fit. | X35: [dex import] military course: ט · education: פסגות · tags: 25/2/2026 - Closing Event,Fireside Chat,Apex Newsletter,Signed To Apex,Architect Cohort #2,Apex Grad
A36: 34 | B36: Guy Yoshpe | D36: #2 | F36: ARAM | G36: Wiz | H36: Building | I36: Israel | J36: security | K36: A | T36: https://www.linkedin.com/in/yoshpe | U36: yoshpe@gmail.com | V36: +972508717313 | W36: Proven founder-CTO now at Wiz. Elite cloud engineering environment; application/cloud layer rather than GPU/power systems.
A37: 37 | B37: Hila Shmuel | D37: #2 | F37: ARAM | G37: Cabinet (AI workspace) | H37: Co-Founder | I37: Tel-Aviv District, Israel | J37: ai-ml | K37: A | T37: https://www.linkedin.com/in/hilashmuel/ | U37: hila4321@gmail.com | V37: +972508871171 | W37: AI-product founder. Founder DNA, committed, different layer of the stack. | X37: [dex import] military course: יב · met with: Raised · education: אר״מ · tags: Fireside Chat,Apex Newsletter,Signed To Apex,25/2/2026 - Closing Event,Apex Grad
A38: 51 | B38: Iddan Golomb | D38: #2 | F38: Talpiot | G38: Sayata | H38: Co-Founder & CPO | I38: Israel | J38: product-gtm | K38: A | T38: https://www.linkedin.com/in/iddangolomb/ | U38: igolomb@gmail.com | V38: +972542421974 | W38: Product co-founder. Founder DNA, committed, product-side. | X38: [dex import] military course: 25 · education: תלפיות · tags: 25/2/2026 - Closing Event,Fireside Chat,Apex Newsletter,Signed To Apex,Architect Cohort #2,Apex Grad
A39: 50 | B39: Ido Kazma | D39: #2 | F39: Talpiot | G39: Q.ai | H39: Algo Team Lead | I39: Israel | J39: ai-ml | K39: B | T39: https://www.linkedin.com/in/idokazma | U39: idokazma@gmail.com | V39: +972528584131 | W39: Algorithms team lead. Relevant optimization skills, no systems/power record. | X39: [dex import] military course: 31 · education: תלפיות · tags: 25/2/2026 - Closing Event,Fireside Chat,Apex Newsletter,Signed To Apex,Architect Cohort #2,Apex Grad
A40: 29 | B40: Ilan Voronel | D40: #2 | F40: Talpiot | G40: Glassbox | H40: ML & DS Team Leader | I40: Israel | J40: ai-ml | K40: B | T40: https://www.linkedin.com/in/ilan-voronel/ | U40: ilan.voronel@gmail.com | V40: +972547397052 | W40: ML/DS team leadership. No systems/power record. | X40: [dex import] military course: 24 · education: תלפיות · tags: Fireside Chat,Apex Newsletter,Signed To Apex,25/2/2026 - Closing Event,Architect Cohort #2,Apex Grad
...

Sheet KPI Tracker
A1: Weekly KPIs
A2: §17 — not every number rises every week. We are looking for trend and quality. Grey columns compute themselves from the Call Schedule and the Roster; yellow ones you fill in on Thursday.
A4: Week of | B4: Qtr | C4: Calls planned | D4: Calls done | E4: Alumni info updated | F4: Quality connections | G4: Connections → outcome | H4: Alumni who helped an alum | I4: Office Hours contributors | J4: New SF relationships | K4: Moved Avishag → Nadav | L4: Needed Avishag | M4: What I learned / recommend
A5: Weekly target | D5: 4 | E5: 4 | F5: 3 | G5: 1 | H5: 2 | I5: 1 | J5: 1 | K5: 2 | L5: 2
A6: 46271 | B6: Q1 | C6: =COUNTIFS('Call Schedule'!$A$2:$A$190,">="&$A6,'Call Schedule'!$A$2:$A$190,"<="&$A6+6) | D6: =COUNTIFS('Call Schedule'!$A$2:$A$190,">="&$A6,'Call Schedule'!$A$2:$A$190,"<="&$A6+6,'Call Schedule'!$L$2:$L$190,"done") | E6: =COUNTIFS(Roster!$P$2:$P$98,">="&$A6,Roster!$P$2:$P$98,"<="&$A6+6)
A7: 46278 | B7: Q1 | C7: =COUNTIFS('Call Schedule'!$A$2:$A$190,">="&$A7,'Call Schedule'!$A$2:$A$190,"<="&$A7+6) | D7: =COUNTIFS('Call Schedule'!$A$2:$A$190,">="&$A7,'Call Schedule'!$A$2:$A$190,"<="&$A7+6,'Call Schedule'!$L$2:$L$190,"done") | E7: =COUNTIFS(Roster!$P$2:$P$98,">="&$A7,Roster!$P$2:$P$98,"<="&$A7+6)
A8: 46285 | B8: Q1 | C8: =COUNTIFS('Call Schedule'!$A$2:$A$190,">="&$A8,'Call Schedule'!$A$2:$A$190,"<="&$A8+6) | D8: =COUNTIFS('Call Schedule'!$A$2:$A$190,">="&$A8,'Call Schedule'!$A$2:$A$190,"<="&$A8+6,'Call Schedule'!$L$2:$L$190,"done") | E8: =COUNTIFS(Roster!$P$2:$P$98,">="&$A8,Roster!$P$2:$P$98,"<="&$A8+6)
A9: 46299 | B9: Q1 | C9: =COUNTIFS('Call Schedule'!$A$2:$A$190,">="&$A9,'Call Schedule'!$A$2:$A$190,"<="&$A9+6) | D9: =COUNTIFS('Call Schedule'!$A$2:$A$190,">="&$A9,'Call Schedule'!$A$2:$A$190,"<="&$A9+6,'Call Schedule'!$L$2:$L$190,"done") | E9: =COUNTIFS(Roster!$P$2:$P$98,">="&$A9,Roster!$P$2:$P$98,"<="&$A9+6)
A10: 46306 | B10: Q1 | C10: =COUNTIFS('Call Schedule'!$A$2:$A$190,">="&$A10,'Call Schedule'!$A$2:$A$190,"<="&$A10+6) | D10: =COUNTIFS('Call Schedule'!$A$2:$A$190,">="&$A10,'Call Schedule'!$A$2:$A$190,"<="&$A10+6,'Call Schedule'!$L$2:$L$190,"done") | E10: =COUNTIFS(Roster!$P$2:$P$98,">="&$A10,Roster!$P$2:$P$98,"<="&$A10+6)
A11: 46313 | B11: Q1 | C11: =COUNTIFS('Call Schedule'!$A$2:$A$190,">="&$A11,'Call Schedule'!$A$2:$A$190,"<="&$A11+6) | D11: =COUNTIFS('Call Schedule'!$A$2:$A$190,">="&$A11,'Call Schedule'!$A$2:$A$190,"<="&$A11+6,'Call Schedule'!$L$2:$L$190,"done") | E11: =COUNTIFS(Roster!$P$2:$P$98,">="&$A11,Roster!$P$2:$P$98,"<="&$A11+6)
A12: 46320 | B12: Q1 | C12: =COUNTIFS('Call Schedule'!$A$2:$A$190,">="&$A12,'Call Schedule'!$A$2:$A$190,"<="&$A12+6) | D12: =COUNTIFS('Call Schedule'!$A$2:$A$190,">="&$A12,'Call Schedule'!$A$2:$A$190,"<="&$A12+6,'Call Schedule'!$L$2:$L$190,"done") | E12: =COUNTIFS(Roster!$P$2:$P$98,">="&$A12,Roster!$P$2:$P$98,"<="&$A12+6)
A13: 46327 | B13: Q1 | C13: =COUNTIFS('Call Schedule'!$A$2:$A$190,">="&$A13,'Call Schedule'!$A$2:$A$190,"<="&$A13+6) | D13: =COUNTIFS('Call Schedule'!$A$2:$A$190,">="&$A13,'Call Schedule'!$A$2:$A$190,"<="&$A13+6,'Call Schedule'!$L$2:$L$190,"done") | E13: =COUNTIFS(Roster!$P$2:$P$98,">="&$A13,Roster!$P$2:$P$98,"<="&$A13+6)
A14: 46334 | B14: Q1 | C14: =COUNTIFS('Call Schedule'!$A$2:$A$190,">="&$A14,'Call Schedule'!$A$2:$A$190,"<="&$A14+6) | D14: =COUNTIFS('Call Schedule'!$A$2:$A$190,">="&$A14,'Call Schedule'!$A$2:$A$190,"<="&$A14+6,'Call Schedule'!$L$2:$L$190,"done") | E14: =COUNTIFS(Roster!$P$2:$P$98,">="&$A14,Roster!$P$2:$P$98,"<="&$A14+6)
A15: 46341 | B15: Q1 | C15: =COUNTIFS('Call Schedule'!$A$2:$A$190,">="&$A15,'Call Schedule'!$A$2:$A$190,"<="&$A15+6) | D15: =COUNTIFS('Call Schedule'!$A$2:$A$190,">="&$A15,'Call Schedule'!$A$2:$A$190,"<="&$A15+6,'Call Schedule'!$L$2:$L$190,"done") | E15: =COUNTIFS(Roster!$P$2:$P$98,">="&$A15,Roster!$P$2:$P$98,"<="&$A15+6)
A16: 46348 | B16: Q1 | C16: =COUNTIFS('Call Schedule'!$A$2:$A$190,">="&$A16,'Call Schedule'!$A$2:$A$190,"<="&$A16+6) | D16: =COUNTIFS('Call Schedule'!$A$2:$A$190,">="&$A16,'Call Schedule'!$A$2:$A$190,"<="&$A16+6,'Call Schedule'!$L$2:$L$190,"done") | E16: =COUNTIFS(Roster!$P$2:$P$98,">="&$A16,Roster!$P$2:$P$98,"<="&$A16+6)
A17: 46355 | B17: Q1 | C17: =COUNTIFS('Call Schedule'!$A$2:$A$190,">="&$A17,'Call Schedule'!$A$2:$A$190,"<="&$A17+6) | D17: =COUNTIFS('Call Schedule'!$A$2:$A$190,">="&$A17,'Call Schedule'!$A$2:$A$190,"<="&$A17+6,'Call Schedule'!$L$2:$L$190,"done") | E17: =COUNTIFS(Roster!$P$2:$P$98,">="&$A17,Roster!$P$2:$P$98,"<="&$A17+6)
... A55: 46621 | B55: Q4 | C55: =COUNTIFS('Call Schedule'!$A$2:$A$190,">="&$A55,'Call Schedule'!$A$2:$A$190,"<="&$A55+6) | D55: =COUNTIFS('Call Schedule'!$A$2:$A$190,">="&$A55,'Call Schedule'!$A$2:$A$190,"<="&$A55+6,'Call Schedule'!$L$2:$L$190,"done") | E55: =COUNTIFS(Roster!$P$2:$P$98,">="&$A55,Roster!$P$2:$P$98,"<="&$A55+6)
A58: The funnel (§19)
A59: Counted off Tie strength in the Roster. Far more meaningful than 'I did 17 calls'. Early on it will look thin — report it thin.
A61: Alumni | B61: Known | C61: Connected | D61: Engaged | E61: Contributor | F61: Node
A62: =COUNTA(Roster!$B$2:$B$98) | B62: =COUNTIF(Roster!$L$2:$L$98,"Known") | C62: =COUNTIF(Roster!$L$2:$L$98,"Connected") | D62: =COUNTIF(Roster!$L$2:$L$98,"Engaged") | E62: =COUNTIF(Roster!$L$2:$L$98,"Contributor") | F62: =COUNTIF(Roster!$L$2:$L$98,"Node")
A64: Dependency on Avishag (§18)
A65: What share of the week's items closed without her. 100% is not the goal — less over time is.
A67: Items handled this week
A68: Of those, closed without Avishag
A69: % handled independently | B69: =IF($B67=0,0,$B68/$B67)
A72: Three lines, every Thursday (§21)
A73: מה למדתי — what did I learn about our people this week?
A74: מה אני ממליץ — what should APEX do about it?
A75: מה אני צריך מאבישג — max three. Zero is better.

Sheet Q1 90-Day Test
A1: The 90-day test
A2: §24 — in ninety days these must be answerable without asking anyone. Q1 is built backwards from them. Deadline: 30 Nov 2026.
A4: # | B4: The question §24 asks | C4: What has to exist for it to be answerable | D4: Where it is tracked | E4: Status
A5: 1 | B5: Who are our 20 strongest alumni? | C5: All 27 tier-A alumni called at least once | D5: Call Schedule, filter Tier = A
A6: 2 | B6: What is each of them doing right now? | C6: Now / current goal filled for every tier-A row | D6: Roster, column M
A7: 3 | B7: Who is on the way to founding? | C7: The founding-track question asked on every tier-A call | D7: Roster, Notes + Now
A8: 4 | B8: What does each of them need? | C8: Needs filled for every tier-A row | D8: Roster, column N
A9: 5 | B9: What can each of them help with? | C9: Can help with filled for every tier-A row | D9: Roster, column O
A10: 6 | B10: Who already helps others? | C10: Tie strength set to Contributor or Node where true | D10: Roster, column L
A11: 7 | B11: Who are our people in SF? | C11: SF phases 1–2 done — circle mapped, key people met | D11: Projects sheet
A12: 8 | B12: Do we have the first 20 Office Hours contributors? | C12: 8 recruited by 30 Nov, with the anti-abuse model researched first | D12: Projects sheet
A13: 9 | B13: Which relationships moved from Avishag to Nadav? | C13: Counted weekly from week one, so a trend exists by Q4 | D13: KPI Tracker, column K
A14: 10 | B14: The 16 alumni with no verified role | C14: Role and company established for each | D14: Roster, filter Role = blank
A15: 11 | B15: If Avishag vanished for a month, would the network keep strengthening? | C15: The honest answer, written down | D15: Thursday report
B17: Tier-A calls completed | C17: =COUNTIFS('Call Schedule'!$G$2:$G$190,"A",'Call Schedule'!$L$2:$L$190,"done")
B18: Roster rows with Needs filled | C18: =COUNTA(Roster!$N$2:$N$98)
B19: Roster rows still with no verified role | C19: =COUNTIF(Roster!$H$2:$H$98,"Unknown*")

Sheet Projects
A1: Standing projects
A2: §9–§12. Dates are the plan's; owners and status are yours.
A4: Project | B4: What it is | C4: Target | D4: When | E4: Status | F4: Notes
A5: Alumni Roll-Up | B5: A live picture of every alum — not a list of names. Done when every row carries role, company, current goal and a next action. | C5: 16 unknowns → 0 | D5: By 30 Nov 2026
A6: Coffee Club #1 | B6: Four alumni, one per cohort, plus Avishag and Nadav. Listen through them, and start making each one active in the network. Nobody repeats within the year. Not called Coffee Club out loud. | C6: 4 alumni | D6: Early Oct 2026
A7: Coffee Club #2 | B7: As above — follow-ups from #1 owned by Nadav. | C7: 4 alumni | D7: Early Dec 2026
A8: Coffee Club #3 | B8: As above. | C8: 4 alumni | D8: Feb 2027
A9: Coffee Club #4 | B9: As above. | C9: 4 alumni | D9: Apr 2027
A10: Coffee Club #5 | B10: As above. | C10: 4 alumni | D10: Jun 2027
A11: Coffee Club #6 | B11: As above — closes the cycle with all cohorts. | C11: 4 alumni | D11: Aug 2027
A12: SF · phase 1 | B12: Map the existing circle. | C12: Circle mapped | D12: Q1
A13: SF · phase 2 | B13: Meet the people who matter in it. | C13: Key people met | D13: Q1
A14: SF · phase 3 | B14: Create value there, and stay warm when we need nothing from them. The phase that gets skipped, and the one that decides whether the network is real. | C14: Relationships held | D14: Q2
A15: SF · phase 4 | B15: Extend beyond Avishag's circle. An alum landing in SF walks into an existing network, not a strange city. | C15: Network beyond her | D15: Q3–Q4
A16: Office Hours · research | B16: How other networks run office hours, and above all how they prevent abuse, overload and contributor burnout. Check access, matching, frequency, quality control, fatigue, confidentiality, follow-up. Bring a recommendation, not a launch. | C16: A recommendation | D16: Q1, before launch
... A19: Month without Avishag | B19: Run the §24 test for real, and answer honestly whether the network kept strengthening. | C19: An honest answer | D19: Q4
A21: The introduction gate (§3)
A22: Before connecting two people, answer: why do these two need to know each other now? No good answer, no introduction. The goal is relationships that produce value, not a count of intros. And close the loop with the alum — even when Avishag does not reply, Delgo is the one who makes sure the circle closes.
